Traceback (most recent call last):
  File "/home/kevin/junos-networkAutomation/venv/lib/python3.10/site-packages/netmiko/base_connection.py", line 1046, in establish_connection
    self.remote_conn_pre.connect(**ssh_connect_params)
  File "/home/kevin/junos-networkAutomation/venv/lib/python3.10/site-packages/paramiko/client.py", line 485, in connect
    self._auth(
  File "/home/kevin/junos-networkAutomation/venv/lib/python3.10/site-packages/paramiko/client.py", line 818, in _auth
    raise saved_exception
  File "/home/kevin/junos-networkAutomation/venv/lib/python3.10/site-packages/paramiko/client.py", line 805, in _auth
    self._transport.auth_password(username, password)
  File "/home/kevin/junos-networkAutomation/venv/lib/python3.10/site-packages/paramiko/transport.py", line 1587, in auth_password
    return self.auth_handler.wait_for_response(my_event)
  File "/home/kevin/junos-networkAutomation/venv/lib/python3.10/site-packages/paramiko/auth_handler.py", line 263, in wait_for_response
    raise e
paramiko.ssh_exception.AuthenticationException: Authentication failed.

During handling of the above exception, another exception occurred:

Traceback (most recent call last):
  File "/home/kevin/junos-networkAutomation/venv/lib/python3.10/site-packages/nornir/core/task.py", line 99, in start
    r = self.task(self, **self.params)
  File "/home/kevin/junos-networkAutomation/venv/lib/python3.10/site-packages/nornir_netmiko/tasks/netmiko_send_command.py", line 26, in netmiko_send_command
    net_connect = task.host.get_connection(CONNECTION_NAME, task.nornir.config)
  File "/home/kevin/junos-networkAutomation/venv/lib/python3.10/site-packages/nornir/core/inventory.py", line 494, in get_connection
    self.open_connection(
  File "/home/kevin/junos-networkAutomation/venv/lib/python3.10/site-packages/nornir/core/inventory.py", line 546, in open_connection
    conn_obj.open(
  File "/home/kevin/junos-networkAutomation/venv/lib/python3.10/site-packages/nornir_netmiko/connections/netmiko.py", line 59, in open
    connection = ConnectHandler(**parameters)
  File "/home/kevin/junos-networkAutomation/venv/lib/python3.10/site-packages/netmiko/ssh_dispatcher.py", line 365, in ConnectHandler
    return ConnectionClass(*args, **kwargs)
  File "/home/kevin/junos-networkAutomation/venv/lib/python3.10/site-packages/netmiko/base_connection.py", line 439, in __init__
    self._open()
  File "/home/kevin/junos-networkAutomation/venv/lib/python3.10/site-packages/netmiko/base_connection.py", line 444, in _open
    self.establish_connection()
  File "/home/kevin/junos-networkAutomation/venv/lib/python3.10/site-packages/netmiko/base_connection.py", line 1083, in establish_connection
    raise NetmikoAuthenticationException(msg)
netmiko.exceptions.NetmikoAuthenticationException: Authentication to device failed.

Common causes of this problem are:
1. Invalid username and password
2. Incorrect SSH-key file
3. Connecting to the wrong device

Device settings: juniper_junos 10.1.8.131:22


Authentication failed.
